Workbook

Sheet Anleitung
A1: Artikelverwaltung Betriebsauflösung – Kurzanleitung
A2: Diese Datei liegt in OneDrive und ist die einzige Quelle der Wahrheit. Bitte immer direkt hier arbeiten – nicht herunterladen, bearbeiten und wieder hochladen.
A4: Die Blätter
A5: Artikelstamm | B5: Alle Artikel. Hier wird gepflegt. Grau hinterlegte Spalten sind die Felder zum Ausfüllen, alles andere rechnet sich selbst oder bleibt stehen.
A6: Verkaufsübersicht | B6: Reines Auswertungsblatt. Umsatz, offene Rechnungen, Restbestand – rechnet automatisch. Hier nichts eintragen.
A7: Kasse | B7: Barverkäufe je Tag für das Kassenbuch. Pflicht bei einer GmbH (GoBD).
A9: Die wichtigsten Regeln
A10: Ein Artikel verkauft | B10: Status auf „verkauft“, Verkaufspreis, Verkaufte Menge, Käufer und Datum eintragen. Der Rest rechnet sich.
A11: Reservierung | B11: Status auf „reserviert“, Name und Abholtermin eintragen. Ohne Abholtermin keine Reservierung – sonst blockiert die Ware.
A12: Restmenge | B12: Rechnet sich aus Menge minus verkaufter Menge. Nicht überschreiben.
A13: Preise | B13: Endpreis pro Einheit. Die Spalte heißt weiter Preis_netto, es wird aber keine Umsatzsteuer aufgeschlagen: steuerfreie Lieferung gemäß § 4 Nr. 28 UStG.
A14: Wertklasse | B14: A = Wertträger, einzeln vermarkten · B = Einzelposition im Katalog · C = Kleinteil, geht in den Verkaufstag.
A15: Barzahlung | B15: Seit Oktober 2026 wird nur überwiesen. Falls doch einmal bar bezahlt wird: zusätzlich im Blatt „Kasse“ erfassen.
A16: Anlagennummer | B16: Wenn bekannt eintragen – der Steuerberater braucht sie für den Anlagenabgang.
A18: Hinweise zu den Preisen | B18: Alle Preise in dieser Datei sind Schätzwerte auf Basis der Fotos. Sie sind zur Überarbeitung gedacht.
A19: Preis_geprüft | B19: „offen“ = Preis ist noch geschätzt und muss kontrolliert werden (dunkelgrau hinterlegt). Nach der Kontrolle „ok“ eintragen. Filter auf „offen“ zeigt die Prüfliste. Artikel mit „offen“ gehen nicht in den Webkatalog.
A20: Markenware | B20: Vitra, Stokke, USM Haller und Kartell sind dort vermerkt, wo die Marke am Stück belegt ist. Für diese Stücke gibt es einen eigenen Gebrauchtmarkt mit Fachhändlern – dort sind höhere Preise erzielbar als im Sammelangebot.
A21: Kunst | B21: Die Acrylbilder sind Eigenarbeiten einer Privatperson, die Schwarzwald-Trachtenmotive sind Kaufware. Beides ist in der Beschreibung vermerkt.
A23: Für die Prüfrunde
A24: So geht es am schnellsten | B24: Von oben nach unten durchgehen: Bild und Bezeichnung ansehen, Preis_netto prüfen oder überschreiben, weiter. Die Räume stehen zusammen, es ist also ein Rundgang durchs Haus.
A25: Was angefasst wird | B25: Nur vier Spalten: Preis_netto, Anlagennr, Anschaffungswert_netto und – falls etwas gar nicht angeboten werden soll – Im_Katalog auf „nein“. Alles andere kann so bleiben.
A26: Was man lassen sollte | B26: Keine Zeilen löschen. Eine fehlende Zeile wird beim Einlesen als „entfällt“ gewertet und verschwindet aus dem Katalog. Soll etwas raus, bitte Aktiv auf „entfällt“ setzen.
A27: Das Bild in Spalte A | B27: Jede Zeile zeigt links das Foto des Artikels – dasselbe Bild, das später im Webkatalog steht. So lässt sich der Preis direkt am Stück beurteilen, ohne die Fotos daneben zu öffnen.
A28: Filtern statt Sortieren | B28: Zum Eingrenzen bitte den Filter in Zeile 2 benutzen (z. B. nur ein Raum). Sortieren ist in diesem Blatt gesperrt: Excel ordnet dabei zwar die Zeilen um, lässt die Bilder aber stehen – danach stünde jedes Foto beim falschen Artikel.
A29: Zugeklappte Spalten | B29: Zweimal sind Spalten als Gruppe zugeklappt: die Detailangaben (Kategorie bis Maße) und ganz rechts die Verkaufsspalten. So steht Preis_netto gleich neben Bild und Bezeichnung. Das Plus über der Spaltenleiste klappt sie auf.
A30: Formeln | B30: Restmenge, Positionswert und Umsatz rechnen sich selbst und sind gegen Überschreiben geschützt.

Sheet Artikelstamm
A1: STAMMDATEN | Q1: BUCHHALTUNG | S1: PREIS | W1: VERMARKTUNG | AE1: VERKAUF | AI1: KAUFMÄNNISCH | AM1: NOTIZEN
A2: Bild | B2: ArtNr | C2: Raumcode | D2: Raum | E2: Bezeichnung | F2: Menge | G2: Beschreibung | H2: Kategorie | I2: Weitere_ArtNr | J2: Wertklasse | K2: Einheit | L2: Maße | M2: Zustand | N2: Verkauft_Menge | O2: Restmenge | P2: Aktiv | Q2: Anlagennr | R2: Anschaffungswert_netto | S2: Preis_netto | T2: Preisbasis | U2: Preis_geprüft | V2: Positionswert_netto | W2: Versand | X2: Foto | Y2: Im_Katalog | Z2: Status | AA2: Marke | AB2: Bündel | AC2: Kanal | AD2: Reserviert_für | AE2: Verkaufspreis_netto | AF2: Umsatz_netto | AG2: Verkaufsdatum | AH2: Käufer | AI2: Rechnungsnr | AJ2: Zahlung | AK2: Zahlart | AL2: Abholtermin | AM2: Mengenhinweis | AN2: Bemerkung
B3: BA04-01 | C3: BA04 | D3: Gruppenraum | E3: Rattankörbe 8 Stück | F3: 1 | G3: Rattankörbe 8 Stück | H3: Deko | J3: C | K3: Set | M3: gebraucht | O3: =F3-IF(N3="",0,N3) | P3: ja | S3: 40 | T3: Fix | U3: ok | V3: =O3*S3 | W3: nur Abholung | X3: F-062 | Y3: ja | Z3: reserviert | AC3: Webkatalog | AD3: Ann - Katrin Fischer | AF3: =IF(N3="","",N3*AE3) | AL3: 22.10.2026 15:00 | AM3: 1 Set Körbe. Ohne Regal | AN3: Notiz aus der ersten Liste: 1 Regal mit 6 Körben im Bild · Webkatalog: Barzahlung
B4: BA04-02 | C4: BA04 | D4: Gruppenraum | E4: Holzkiste Obstkistenoptik | F4: 4 | G4: Alte Holzkiste, unbehandelt, als Aufbewahrung | H4: Deko | J4: C | K4: Stück | M4: gebraucht | O4: =F4-IF(N4="",0,N4) | P4: entfällt | S4: 15 | T4: Fix | V4: =O4*S4 | W4: nur Abholung | X4: F-063 | Y4: ja | Z4: verfügbar | AF4: =IF(N4="","",N4*AE4)
B5: BA08-01 | C5: BA08 | D5: Atelier | E5: Konvolut Mal- und Bastelfarben | F5: 1 | G5: Creall Fingerpaint: jeweils 1 angefangene Flasche braun, gelb, hellrosa, dunkelrot, violett, weiß und hellblau; jeweils 1 ungeöffnete Flasche schwarz, blau, dunkelblau, hellgrün und hellblau; Insgesamt Plakatfarbe (Moje Bambino) 2 ungeöffnete Flaschen braun, weiß, violett und schwarz, 1 ungeöffnete Flasche orange, grün, dunkelblau und gelb, 3 ungeöffnete Flaschen hellrosa und rot sowie jeweils ca. 1/2 Flasche gelb, hellrosa, violett, jeweils angebraucht ( nur geringe Menge entnommen) 2x blau, 2x dunkelblau 1x hellgrün und 1x orange | H5: Verbrauchsmaterial | J5: C | K5: Konvolut | M5: gebraucht | O5: =F5-IF(N5="",0,N5) | P5: ja | S5: 120 | T5: Fix | U5: ok | V5: =O5*S5 | W5: nur Abholung | X5: F-065 | Y5: ja | Z5: verfügbar | AF5: =IF(N5="","",N5*AE5) | AM5: div. Farben der Farbpalette, teilweise bereits angebraucht
B6: BA08-02 | C6: BA08 | D6: Atelier | E6: Acrylfarben-Sortiment | F6: 1 | G6: Karton mit Acrylfarben 2xgrau, 1x blau, 2x dunkelbraun, 1x grün, 1x gelb (bereits angebraucht), 1x hellgrün 2x rot, 3x hellbraun, 1x türkis, 2x oliv, 1x orange, 3x phtalo grün, 4x braun Herstellungsdatum: 10/24; bis auf eine Tube sind alle Farben unbenutzt | H6: Verbrauchsmaterial | J6: C | K6: Konvolut | M6: neuwertig | O6: =F6-IF(N6="",0,N6) | P6: entfällt | S6: 48 | T6: Fix | U6: ok | V6: =O6*S6 | W6: nur Abholung | X6: F-546 | Y6: ja | Z6: verfügbar | AF6: =IF(N6="","",N6*AE6) | AN6: 13.10.2026: auf Wunsch der Nutzerin aus dem Katalog (entfällt).
B7: BA08-03 | C7: BA08 | D7: Atelier | E7: Konvolut Bastelmaterial | F7: 1 | G7: 1 Karton Bastelmaterial bestehend aus diverse Kunststoff-Perlen, Bänder, Glitzer, Holzperlen, Bügelperlen, Schnüre alles in verschiedenen Farben und Formen; Basteldraht, Streuglitzer,Sand etc. | H7: Verbrauchsmaterial | J7: C | K7: Konvolut | M7: gut | N7: 1 | O7: =F7-IF(N7="",0,N7) | P7: ja | S7: 50 | T7: Fix | U7: ok | V7: =O7*S7 | W7: nur Abholung | X7: F-070 | Y7: ja | Z7: verkauft | AC7: Webkatalog | AE7: 50 | AF7: =IF(N7="","",N7*AE7) | AG7: 14.10.2026 | AH7: Maren Kipp | AI7: 4000114 | AJ7: bezahlt | AL7: 09.11.2026 08:00
B8: BA08-04 | C8: BA08 | D8: Atelier | E8: buntes Tonpapier | F8: 1 | G8: buntes Tonpapier -70x50cm 1x schwarz, 5x weiß, 4x rot; 9x hochrot, 11x gelb, 6x orange, 8x lila, 4x hellblau, 5x dunkelblau 5x blau, 12x hellgrün, 19x dunkelgrün Größe 60x42: 16x pink, 2x dunkelgrün; 42x30cm: 19x pink | H8: Verbrauchsmaterial | J8: B | K8: Konvolut | M8: neuwertig | O8: =F8-IF(N8="",0,N8) | P8: ja | S8: 50 | T8: Fix | U8: ok | V8: =O8*S8 | W8: nur Abholung | X8: F-555 | Y8: ja | Z8: verfügbar | AF8: =IF(N8="","",N8*AE8) | AM8: verschiedene Farben und Größen
B9: BA09-01 | C9: BA09 | D9: Personalraum | E9: Deko Metallruten mit Pompons | F9: 2 | G9: Metallruten mit roten Wollbommeln in Birkenstammfuß | H9: Deko | J9: C | K9: Stück | M9: gut | O9: =F9-IF(N9="",0,N9) | P9: ja | S9: 15 | T9: Fix | U9: ok | V9: =O9*S9 | W9: nur Abholung | X9: F-044 | Y9: ja | Z9: verfügbar | AF9: =IF(N9="","",N9*AE9) | AN9: Notiz aus der ersten Liste: 2 Stück im Bild
B10: BA09-02 | C10: BA09 | D10: Personalraum | E10: Elefantenfuß groß | F10: 1 | G10: Beaucarnea, große Zimmerpflanze im Topf und kleine Zimmerpflanze im Topf | H10: Pflanzen | J10: C | K10: Set | M10: gut | O10: =F10-IF(N10="",0,N10) | P10: ja | S10: 30 | T10: Fix | U10: ok | V10: =O10*S10 | W10: nur Abholung | X10: F-045 | Y10: ja | Z10: verfügbar | AF10: =IF(N10="","",N10*AE10) | AN10: Notiz aus der ersten Liste: 1 Pflanze im Bild
B11: BA09-03 | C11: BA09 | D11: Personalraum | E11: Werte-Rad | F11: 1 | G11: Drehbares Holzrad zur Visualisierung von Leitwerten, Eigenbau | H11: Kita-Ausstattung | J11: C | K11: Stück | M11: gut | O11: =F11-IF(N11="",0,N11) | P11: ja | S11: 40 | T11: Fix | U11: ok | V11: =O11*S11 | W11: nur Abholung | X11: F-046 | Y11: ja | Z11: verfügbar | AF11: =IF(N11="","",N11*AE11) | AN11: Notiz aus der ersten Liste: 1 Stück im Bild
B12: BA09-04 | C12: BA09 | D12: Personalraum | E12: USM Haller Tisch | F12: 1 | G12: USM Haller, weiße Tischplatte, verchromtes Rohrgestell mit Kugelverbindern, ca. 200 x 100 cm | H12: Möbel | J12: A | K12: Stück | M12: gut | O12: =F12-IF(N12="",0,N12) | P12: ja | S12: 750 | T12: VHB | U12: ok | V12: =O12*S12 | W12: nur Abholung | X12: F-047 | Y12: ja | Z12: verfügbar | AA12: USM Haller | AB12: Designklassiker | AF12: =IF(N12="","",N12*AE12) | AN12: Notiz aus der ersten Liste: 1 Tisch im Bild
B13: BA09-05 | C13: BA09 | D13: Personalraum | E13: Kartell Masters Stuhl | F13: 4 | G13: Kartell Masters, Design Philippe Starck, schwarz | H13: Möbel | J13: A | K13: Stück | M13: gebraucht | O13: =F13-IF(N13="",0,N13) | P13: ja | Q13: 670026 | R13: 690.02 | S13: 120 | T13: Fix | U13: ok | V13: =O13*S13 | W13: nur Abholung | X13: F-048 | Y13: ja | Z13: verfügbar | AA13: Kartell | AB13: Designklassiker | AF13: =IF(N13="","",N13*AE13) | AM13: insgesamt 4 Stück
B14: BA10-01 | C14: BA10 | D14: Ruheraum | E14: Glastisch rund mit Chromgestell | F14: 1 | G14: Runde Glasplatte teilsatiniert, Chromgestell inkl. 4 Stühle 105 cm Durchmesser | H14: Möbel | J14: B | K14: Stück | M14: gebraucht | O14: =F14-IF(N14="",0,N14) | P14: ja | S14: 150 | T14: Fix | U14: ok | V14: =O14*S14 | W14: nur Abholung | X14: F-057 | Y14: ja | Z14: verfügbar | AF14: =IF(N14="","",N14*AE14) | AN14: Notiz aus der ersten Liste: 1 Tisch im Bild
B15: BA10-02 | C15: BA10 | D15: Ruheraum | E15: Samtsofa bordeaux, 2-Sitzer | F15: 2 | G15: Samtbezug dunkelrot, gesteppte Rückenlehne, dunkle Holzbeine ca. 160cm breit | H15: Möbel | J15: B | K15: Stück | M15: gebraucht | O15: =F15-IF(N15="",0,N15) | P15: ja | Q15: 670017 | R15: 585.33 | S15: 300 | T15: VHB | U15: ok | V15: =O15*S15 | W15: nur Abholung | X15: F-058 | Y15: ja | Z15: verfügbar | AF15: =IF(N15="","",N15*AE15) | AN15: Notiz aus der ersten Liste: 1 Sofa im Bild
B16: BA10-03 | C16: BA10 | D16: Ruheraum | E16: Sessel mit Bezug, weiß lackiert | F16: 2 | G16: Relaxsessel Alcantara, Alu, hellgrauer Bezug, mit Nackenkissen; Sitzteil ausziehbar als Fußauflage; Lehne verstellbar | H16: Möbel | J16: C | K16: Stück | M16: gebraucht | O16: =F16-IF(N16="",0,N16) | P16: ja | S16: 200 | T16: VHB | U16: ok | V16: =O16*S16 | W16: nur Abholung | X16: F-591 | Y16: ja | Z16: verfügbar | AF16: =IF(N16="","",N16*AE16) | AN16: Notiz aus der ersten Liste: 1 Sessel im Bild
B17: BA10-04 | C17: BA10 | D17: Ruheraum | E17: Hocker grau mit Hairpin-Beinen | F17: 1 | G17: Hocker grau Runder Polsterhocker grau, mit Stauraum ohne Deko | H17: Möbel | J17: C | K17: Stück | M17: gebraucht | O17: =F17-IF(N17="",0,N17) | P17: ja | S17: 35 | T17: Fix | U17: ok | V17: =O17*S17 | W17: nur Abholung | X17: F-592 | Y17: ja | Z17: verfügbar | AF17: =IF(N17="","",N17*AE17)
B18: BA10-05 | C18: BA10 | D18: Ruheraum | E18: Ohrensessel grau mit Kufengestell | F18: 2 | G18: Polstersessel hellgrau, schwarzes Kufengestell aus Rundstahl ohne Kissen / Auflage | H18: Möbel | J18: B | K18: Stück | M18: gebraucht | N18: 2 | O18: =F18-IF(N18="",0,N18) | P18: ja | S18: 100 | T18: Fix | U18: ok | V18: =O18*S18 | W18: nur Abholung | X18: F-594 | Y18: ja | Z18: verkauft | AC18: Webkatalog | AE18: 100 | AF18: =IF(N18="","",N18*AE18) | AG18: 16.10.2026 | AH18: Christian Migowski, Boos | AI18: 4000135, 4000116 | AJ18: bezahlt | AL18: 21.10.2026 07:30, 26.10.2026 08:00 | AN18: Notiz aus der ersten Liste: 2 Sessel im Bild
B19: BA10-06 | C19: BA10 | D19: Ruheraum | E19: Hocker grau, passend | F19: 2 | G19: Polsterhocker hellgrau, schwarzes Kufengestell, passend zu den Sesseln 45x50cm | H19: Möbel | J19: C | K19: Stück | M19: gebraucht | N19: 2 | O19: =F19-IF(N19="",0,N19) | P19: ja | S19: 30 | T19: Fix | U19: ok | V19: =O19*S19 | W19: nur Abholung | X19: F-056 | Y19: ja | Z19: verkauft | AC19: Webkatalog | AE19: 30 | AF19: =IF(N19="","",N19*AE19) | AG19: 16.10.2026 | AH19: Christian Migowski, Boos | AI19: 4000135, 4000116 | AJ19: bezahlt | AL19: 21.10.2026 07:30, 26.10.2026 08:00 | AN19: Notiz aus der ersten Liste: 2 Hocker im Bild
B20: BA10-07 | C20: BA10 | D20: Ruheraum | E20: Beistelltisch rund grau | F20: 1 | G20: Runde Platte grau, schwarze Hairpin-Beine; 50cm Durchmesser | H20: Möbel | J20: C | K20: Stück | M20: gut | O20: =F20-IF(N20="",0,N20) | P20: ja | S20: 30 | T20: Fix | U20: ok | V20: =O20*S20 | W20: nur Abholung | X20: F-593 | Y20: ja | Z20: verfügbar | AF20: =IF(N20="","",N20*AE20) | AN20: Notiz aus der ersten Liste: 1 Tisch im Bild
B21: BA10-08 | C21: BA10 | D21: Ruheraum | E21: Pendelleuchte Drahtgeflecht | F21: 2 | G21: Geometrische Drahtleuchte schwarz, Ikosaederform | H21: Leuchten | J21: C | K21: Stück | M21: gut | O21: =F21-IF(N21="",0,N21) | P21: ja | S21: 55 | T21: Fix | U21: ok | V21: =O21*S21 | W21: nur Abholung | X21: F-061 | Y21: ja | Z21: verfügbar | AF21: =IF(N21="","",N21*AE21) | AN21: Notiz aus der ersten Liste: 1 Leuchte im Bild
B22: BA12-01 | C22: BA12 | D22: Personal-WC | E22: Ast-Mobile mit Papierwaben | F22: 1 | G22: Deko-Mobile: Birkenast mit Papierwaben, Sternen und Filzhäusern | H22: Deko | J22: C | K22: Stück | M22: gut | O22: =F22-IF(N22="",0,N22) | P22: ja | S22: 30 | T22: Fix | U22: ok | V22: =O22*S22 | W22: nur Abholung | X22: F-055 | Y22: ja | Z22: verfügbar | AF22: =IF(N22="","",N22*AE22) | AN22: Notiz aus der ersten Liste: 1 Mobile im Bild
B23: BE01-01 | C23: BE01 | D23: Flur | E23: Barockspiegel schwarz, oval | F23: 3 | G23: Verzierter Rahmen schwarz, oval, zwei Größen | H23: Deko | J23: C | K23: Stück | M23: gut | O23: =F23-IF(N23="",0,N23) | P23: ja | S23: 45 | T23: Fix | U23: ok | V23: =O23*S23 | W23: nur Abholung | X23: F-051 | Y23: ja | Z23: verfügbar | AF23: =IF(N23="","",N23*AE23) | AN23: Notiz aus der ersten Liste: 2 Stück im Bild
B24: BE01-02 | C24: BE01 | D24: Flur | E24: Bilderrahmen mit Kinderzeichnung | F24: 3 | G24: Gerahmte Kinderzeichnungen/Drucke, schwarz gerahmt | H24: Deko | J24: C | K24: Set | M24: gut | O24: =F24-IF(N24="",0,N24) | P24: ja | S24: 30 | T24: Fix | U24: ok | V24: =O24*S24 | W24: nur Abholung | X24: F-053 | Y24: ja | Z24: verfügbar | AF24: =IF(N24="","",N24*AE24) | AN24: Notiz aus der ersten Liste: 3 Rahmen im Bild
B25: BE01-03 | C25: BE01 | D25: Flur | E25: Wandregal-Würfel schwarz | F25: 2 | G25: Offene Regalwürfel zur Wandmontage, schwarz | H25: Möbel | J25: C | K25: Stück | M25: gut | O25: =F25-IF(N25="",0,N25) | P25: ja | S25: 40 | T25: Fix | U25: ok | V25: =O25*S25 | W25: nur Abholung | X25: F-054 | Y25: ja | Z25: verfügbar | AF25: =IF(N25="","",N25*AE25) | AM25: bestehend aus 2 Würfeln | AN25: Sie stehen inzwischen im Atelier (BA08) – die Nummer BE01-03 bleibt.
B26: BE06-01 | C26: BE06 | D26: Gruppenraum | E26: Wandgestell Holz mit Schnüren | F26: 1 | G26: Holzrahmen mit gespannten Schnüren und Wäscheklammern zum Aufhängen von Bildern | H26: Kita-Ausstattung | J26: C | K26: Stück | M26: gebraucht | O26: =F26-IF(N26="",0,N26) | P26: ja | S26: 45 | T26: Fix | U26: ok | V26: =O26*S26 | W26: nur Abholung | X26: F-042 | Y26: ja | Z26: verfügbar | AF26: =IF(N26="","",N26*AE26) | AN26: Notiz aus der ersten Liste: 1 Stück im Bild
B27: BE06-02 | C27: BE06 | D27: Gruppenraum | E27: Designsofa anthrazit | F27: 1 | G27: Geschwungene Form, Wollstoff anthrazit, dunkle Metallbeine, 3-Sitzer | H27: Möbel | J27: A | K27: Stück | M27: gut | N27: 1 | O27: =F27-IF(N27="",0,N27) | P27: ja | Q27: 670012 | R27: 1198 | S27: 650 | T27: VHB | U27: ok | V27: =O27*S27 | W27: nur Abholung | X27: F-043 | Y27: ja | Z27: verkauft | AC27: Webkatalog | AE27: 600 | AF27: =IF(N27="","",N27*AE27) | AG27: 19.10.2026 | AH27: Hagen Rebholz | AI27: 4000133 | AJ27: bezahlt | AL27: 21.10.2026 07:30 | AN27: Notiz aus der ersten Liste: 1 Sofa im Bild
B28: BE10-01 | C28: BE10 | D28: Büro und Besprechung | E28: LED-Ring-Pendelleuchte | F28: 1 | G28: Große Pendelleuchte: mehrere beleuchtete Ringe in unterschiedlichen Größen an dünnen Seilen, 2x 80cm Durchmesser, 2x ca. 60cm Durchmesser | H28: Leuchten | J28: A | K28: Set | M28: gut | N28: 1 | O28: =F28-IF(N28="",0,N28) | P28: ja | S28: 400 | T28: VHB | U28: ok | V28: =O28*S28 | W28: nur Abholung | X28: F-021 | Y28: ja | Z28: verkauft | AC28: Webkatalog | AE28: 400 | AF28: =IF(N28="","",N28*AE28) | AG28: 19.10.2026 | AH28: Hagen Rebholz | AI28: 4000133 | AJ28: bezahlt | AL28: 21.10.2026 07:30 | AM28: Set aus 4 Leuchten (2 × Ø 80 cm, 2 × Ø ca. 60 cm), nur zusammen. | AN28: 16.10.: alle 4 Leuchten als 1 Set für 400 € an Rebholz (#49, RG 4000133).
B29: BE10-02 | C29: BE10 | D29: Büro und Besprechung | E29: Pachira groß im Übertopf | F29: 1 | G29: Glückskastanie, große Pflanze, weißer Übertopf | H29: Pflanzen | J29: C | K29: Stück | M29: gut | O29: =F29-IF(N29="",0,N29) | P29: ja | S29: 80 | T29: Fix | U29: ok | V29: =O29*S29 | W29: nur Abholung | X29: F-025 | Y29: ja | Z29: verfügbar | AF29: =IF(N29="","",N29*AE29) | AN29: Notiz aus der ersten Liste: 1 Pflanze im Bild
B30: BE10-03 | C30: BE10 | D30: Büro und Besprechung | E30: Moderationswand fahrbar | F30: 1 | G30: Pinnwand/Stellwand grau, auf Rollen, beidseitig Höhe Wand: 150; Gesamthöhe: 185cm; Breite: 120cm | H30: Büro | J30: B | K30: Stück | M30: gut | O30: =F30-IF(N30="",0,N30) | P30: ja | S30: 50 | T30: Fix | U30: ok | V30: =O30*S30 | W30: nur Abholung | X30: F-026 | Y30: ja | Z30: reserviert | AC30: Webkatalog | AD30: Ricarda König | AF30: =IF(N30="","",N30*AE30) | AI30: 4000143 | AL30: 16.11.2026 09:00 | AN30: Notiz aus der ersten Liste: 1 Stück im Bild
B31: BE10-04 | C31: BE10 | D31: Büro und Besprechung | E31: Besprechungstisch weiß, Hersteller MDF Italia "Tense" groß 100x270cm | F31: 1 | G31: Konferenztisch Hersteller: MDF Italia "Tense", weiße Platte, für ca. 8-10 Personen | H31: Büro | J31: B | K31: Stück | M31: gut | O31: =F31-IF(N31="",0,N31) | P31: entfällt | S31: 2500 | T31: VHB | V31: =O31*S31 | W31: nur Abholung | X31: F-616 | Y31: ja | Z31: verfügbar | AA31: MDF Italia | AF31: =IF(N31="","",N31*AE31) | AN31: Neues Foto F-616 (Durchsicht 01.10.2026). Entfällt laut Durchsicht 05.10.2026.
B32: BU04-01 | C32: BU04 | D32: Gruppenraum | E32: Crassula im Topf | F32: 2 | G32: Geldbaum, Zimmerpflanze im weißen Topf | H32: Pflanzen | J32: C | K32: Stück | M32: gut | O32: =F32-IF(N32="",0,N32) | P32: ja | S32: 15 | T32: Fix | U32: ok | V32: =O32*S32 | W32: nur Abholung | X32: F-078 | Y32: ja | Z32: verfügbar | AF32: =IF(N32="","",N32*AE32) | AN32: Notiz aus der ersten Liste: 1 Pflanze im Bild
B33: BU04-02 | C33: BU04 | D33: Gruppenraum | E33: Pflanzkübel Raumteiler weiß Hochglanz | F33: 1 | G33: Rechteckiger Pflanzkübel als Raumteiler, weiß hochglanz, ca. 80 x 30 x 80 cm | H33: Pflanzen | J33: B | K33: Stück | M33: gut | O33: =F33-IF(N33="",0,N33) | P33: ja | S33: 150 | T33: Fix | U33: ok | V33: =O33*S33 | W33: nur Abholung | X33: F-079 | Y33: ja | Z33: verfügbar | AF33: =IF(N33="","",N33*AE33) | AM33: inkl. Bepflanzung | AN33: Der Kübel steht inzwischen im Schlafraum 5 (NU04) – die Nummer BU04-02 bleibt.
B34: BU04-03 | C34: BU04 | D34: Gruppenraum | E34: Hochflorteppich beige, rund | F34: 2 | G34: Runder Hochflorteppich in Beige, 100 % Polypropylen, Flor hoch. Etikett auf der Unterseite: IKEA, 195 cm Durchmesser, 9,85 kg. | H34: Textilien | I34: NU02-10 | J34: C | K34: Stück | L34: Ø 195 cm | M34: gebraucht | O34: =F34-IF(N34="",0,N34) | P34: ja | S34: 40 | T34: Fix | U34: ok | V34: =O34*S34 | W34: nur Abholung | X34: F-150 | Y34: ja | Z34: verfügbar | AA34: IKEA | AF34: =IF(N34="","",N34*AE34) | AN34: Zusammengefasste Position – Post-it-Nummer im zweiten Raum: NU02-10. Frueherer Mengenhinweis: 2 Teppiche insgesamt: einer im Gruppenraum (BU04-03) und einer im Gruppenraum 5 (dort mit NU02-10 beschriftet).
B35: BU04-04 | C35: BU04 | D35: Gruppenraum | E35: Regal weiß, 4 Fächer (IKEA Kallax) | F35: 4 | G35: IKEA Kallax 2x2, weiß, vier Fächer. | H35: Möbel | I35: NU02-06 | J35: B | K35: Stück | M35: gebraucht | O35: =F35-IF(N35="",0,N35) | P35: ja | S35: 45 | T35: Fix | U35: ok | V35: =O35*S35 | W35: nur Abholung | X35: F-080 | Y35: ja | Z35: verfügbar | AA35: IKEA | AF35: =IF(N35="","",N35*AE35) | AN35: Zusammengefasste Position – Post-it-Nummer im zweiten Raum: NU02-06. Frueherer Mengenhinweis: 4 Regale insgesamt: 2 im Gruppenraum (BU04-04) und 2 im Gruppenraum 5 (dort mit NU02-06 beschriftet).
B36: K-117 | C36: BU04 | D36: Gruppenraum | E36: Wanddeko Fadenbilder | F36: 5 | G36: Fadenbilder auf Holzreifen, ohne Spiegelelemente; rot und schwarz; unterschiedliche Durchmesser | H36: Deko | J36: C | K36: Set | M36: gut | O36: =F36-IF(N36="",0,N36) | P36: nein | S36: 10 | T36: Fix | V36: =O36*S36 | W36: nur Abholung | X36: F-081 | Y36: nein | Z36: entfällt | AF36: =IF(N36="","",N36*AE36) | AM36: 1 Set im Bild | AN36: Nicht mehr vorhanden – von der Nutzerin am 23.09.2026 bestaetigt. Frueher BU04-05 / K-117; die Nummer BU04-05 klebt jetzt auf den Hochstuehlen. | 12.10.2026: Nummer BU04-16 an das Steckspielzeug abgegeben (Post-it klebt dort), diese entfallene Position trägt wieder ihre alte Nummer K-117.
B37: BU09-01 | C37: BU09 | D37: Werkraum | E37: Wurzelholz-Schale groß | F37: 1 | G37: Dekoschale aus einem Wurzelstück, Teak, ca. 50 cm | H37: Deko | J37: B | K37: Stück | M37: gut | O37: =F37-IF(N37="",0,N37) | P37: ja | S37: 90 | T37: Fix | U37: ok | V37: =O37*S37 | W37: nur Abholung | X37: F-082 | Y37: ja | Z37: verfügbar | AF37: =IF(N37="","",N37*AE37) | AN37: Notiz aus der ersten Liste: 1 Stück im Bild
B38: BU09-02 | C38: BU09 | D38: Werkraum | E38: Konvolut Baumscheiben und Holzscheiben | F38: 1 | G38: Baumscheiben verschiedener Größen und Holzarten, Bastelmaterial ca. 44 grössere mit Durchmesser zwischen 15 und35cm; 35 Stück mit durchmeser ca. 10-15cm | H38: Verbrauchsmaterial | J38: C | K38: Konvolut | M38: gut | N38: 1 | O38: =F38-IF(N38="",0,N38) | P38: ja | S38: 40 | T38: Fix | U38: ok | V38: =O38*S38 | W38: nur Abholung | X38: F-085 | Y38: ja | Z38: verkauft | AC38: Webkatalog | AE38: 40 | AF38: =IF(N38="","",N38*AE38) | AG38: 19.10.2026 | AH38: Sandra Ziegler | AI38: 4000123 | AJ38: bezahlt | AL38: 20.10.2026 14:15 | AM38: Mehrere Kisten mit Baum- und Holzscheiben in verschiedenen Größen | AN38: Notiz aus der ersten Liste: mehrere Kisten im Bild
B39: BU09-03 | C39: BU09 | D39: Werkraum | E39: Kreidetafel in Hausform | F39: 3 | G39: Tafelfolie/Kreidetafel in Hausform, beschriftbar | H39: Kita-Ausstattung | J39: C | K39: Stück | M39: gut | O39: =F39-IF(N39="",0,N39) | P39: ja | S39: 10 | T39: Fix | U39: ok | V39: =O39*S39 | W39: nur Abholung | X39: F-089 | Y39: ja | Z39: verfügbar | AF39: =IF(N39="","",N39*AE39) | AN39: Notiz aus der ersten Liste: 1 Stück im Bild
B40: GA01-01 | C40: GA01 | D40: Garten | E40: Holz-Wellenliege, Doppelliege | F40: 1 | G40: Geschwungene Doppelliege aus Holzlatten, ca. 200 cm breit, | H40: Garten | J40: A | K40: Stück | M40: gut | O40: =F40-IF(N40="",0,N40) | P40: ja | S40: 850 | T40: VHB | U40: ok | V40: =O40*S40 | W40: nur Abholung | X40: F-111 | Y40: ja | Z40: verfügbar | AB40: Außenbereich | AF40: =IF(N40="","",N40*AE40) | AN40: Notiz aus der ersten Liste: 1 Liege im Bild
...

Sheet Verkaufsübersicht
A1: Verkaufsübersicht – rechnet automatisch aus dem Artikelstamm
A2: Hier wird nichts eingetragen. Wer im Artikelstamm einen Verkauf erfasst, sieht ihn sofort hier.
A4: Bestand
A5: Artikelpositionen gesamt | B5: =COUNTA(Artikelstamm!$B$3:$B$729)
A6: davon verfügbar | B6: =COUNTIF(Artikelstamm!$Z$3:$Z$729,"verfügbar")
A7: davon reserviert | B7: =COUNTIF(Artikelstamm!$Z$3:$Z$729,"reserviert")
A8: davon teilverkauft | B8: =COUNTIF(Artikelstamm!$Z$3:$Z$729,"teilverkauft")
A9: davon verkauft | B9: =COUNTIF(Artikelstamm!$Z$3:$Z$729,"verkauft")
A10: Einheiten noch im Bestand | B10: =SUM(Artikelstamm!$O$3:$O$729)
A11: Restbestand zu Wunschpreisen | B11: =SUM(Artikelstamm!$V$3:$V$729)
A12: Erlöse
A13: Verkaufte Einheiten | B13: =SUM(Artikelstamm!$N$3:$N$729)
A14: Umsatz | B14: =SUMPRODUCT(Artikelstamm!$N$3:$N$729,Artikelstamm!$AE$3:$AE$729)
A15: Umsatzsteuer: keine (steuerfrei, § 4 Nr. 28 UStG) | B15: =B14*0.0
A16: Umsatz gesamt | B16: =B14+B15
A17: davon bereits bezahlt | B17: =SUMPRODUCT((Artikelstamm!$AJ$3:$AJ$729="bezahlt")*Artikelstamm!$N$3:$N$729*Artikelstamm!$AE$3:$AE$729)
A18: noch offen | B18: =B14-B17
A20: To-do
A21: Rechnungen noch zu schreiben | B21: =COUNTIFS(Artikelstamm!$Z$3:$Z$729,"*verkauft",Artikelstamm!$AI$3:$AI$729,"")
A22: Rechnungen offen (unbezahlt) | B22: =COUNTIFS(Artikelstamm!$Z$3:$Z$729,"*verkauft",Artikelstamm!$AJ$3:$AJ$729,"offen")
A23: Reservierungen ohne Abholtermin | B23: =COUNTIFS(Artikelstamm!$Z$3:$Z$729,"reserviert",Artikelstamm!$AL$3:$AL$729,"")
A24: Artikel ohne Preis | B24: =COUNTIFS(Artikelstamm!$S$3:$S$729,"")
A25: Artikel ohne Maßangabe | B25: =COUNTIFS(Artikelstamm!$L$3:$L$729,"")
A28: Nach Wertklasse
A29: Wertklasse | B29: Positionen | C29: Umsatz netto | D29: Restwert netto
A30: A | B30: =COUNTIF(Artikelstamm!$J$3:$J$729,$A30) | C30: =SUMPRODUCT((Artikelstamm!$J$3:$J$729=$A30)*Artikelstamm!$N$3:$N$729*Artikelstamm!$AE$3:$AE$729) | D30: =SUMIF(Artikelstamm!$J$3:$J$729,$A30,Artikelstamm!$V$3:$V$729)
A31: B | B31: =COUNTIF(Artikelstamm!$J$3:$J$729,$A31) | C31: =SUMPRODUCT((Artikelstamm!$J$3:$J$729=$A31)*Artikelstamm!$N$3:$N$729*Artikelstamm!$AE$3:$AE$729) | D31: =SUMIF(Artikelstamm!$J$3:$J$729,$A31,Artikelstamm!$V$3:$V$729)
A32: C | B32: =COUNTIF(Artikelstamm!$J$3:$J$729,$A32) | C32: =SUMPRODUCT((Artikelstamm!$J$3:$J$729=$A32)*Artikelstamm!$N$3:$N$729*Artikelstamm!$AE$3:$AE$729) | D32: =SUMIF(Artikelstamm!$J$3:$J$729,$A32,Artikelstamm!$V$3:$V$729)
A33: Summe | B33: =SUM(B30:B32) | C33: =SUM(C30:C32) | D33: =SUM(D30:D32)
A35: Nach Kategorie
A36: Kategorie | B36: Positionen | C36: Umsatz netto | D36: Restwert netto
A37: Büro | B37: =COUNTIF(Artikelstamm!$H$3:$H$729,$A37) | C37: =SUMPRODUCT((Artikelstamm!$H$3:$H$729=$A37)*Artikelstamm!$N$3:$N$729*Artikelstamm!$AE$3:$AE$729) | D37: =SUMIF(Artikelstamm!$H$3:$H$729,$A37,Artikelstamm!$V$3:$V$729)
A38: Deko | B38: =COUNTIF(Artikelstamm!$H$3:$H$729,$A38) | C38: =SUMPRODUCT((Artikelstamm!$H$3:$H$729=$A38)*Artikelstamm!$N$3:$N$729*Artikelstamm!$AE$3:$AE$729) | D38: =SUMIF(Artikelstamm!$H$3:$H$729,$A38,Artikelstamm!$V$3:$V$729)
A39: Garten | B39: =COUNTIF(Artikelstamm!$H$3:$H$729,$A39) | C39: =SUMPRODUCT((Artikelstamm!$H$3:$H$729=$A39)*Artikelstamm!$N$3:$N$729*Artikelstamm!$AE$3:$AE$729) | D39: =SUMIF(Artikelstamm!$H$3:$H$729,$A39,Artikelstamm!$V$3:$V$729)
A40: Kita-Ausstattung | B40: =COUNTIF(Artikelstamm!$H$3:$H$729,$A40) | C40: =SUMPRODUCT((Artikelstamm!$H$3:$H$729=$A40)*Artikelstamm!$N$3:$N$729*Artikelstamm!$AE$3:$AE$729) | D40: =SUMIF(Artikelstamm!$H$3:$H$729,$A40,Artikelstamm!$V$3:$V$729)
A41: Kunst | B41: =COUNTIF(Artikelstamm!$H$3:$H$729,$A41) | C41: =SUMPRODUCT((Artikelstamm!$H$3:$H$729=$A41)*Artikelstamm!$N$3:$N$729*Artikelstamm!$AE$3:$AE$729) | D41: =SUMIF(Artikelstamm!$H$3:$H$729,$A41,Artikelstamm!$V$3:$V$729)
A42: Küchentechnik | B42: =COUNTIF(Artikelstamm!$H$3:$H$729,$A42) | C42: =SUMPRODUCT((Artikelstamm!$H$3:$H$729=$A42)*Artikelstamm!$N$3:$N$729*Artikelstamm!$AE$3:$AE$729) | D42: =SUMIF(Artikelstamm!$H$3:$H$729,$A42,Artikelstamm!$V$3:$V$729)
A43: Leuchten | B43: =COUNTIF(Artikelstamm!$H$3:$H$729,$A43) | C43: =SUMPRODUCT((Artikelstamm!$H$3:$H$729=$A43)*Artikelstamm!$N$3:$N$729*Artikelstamm!$AE$3:$AE$729) | D43: =SUMIF(Artikelstamm!$H$3:$H$729,$A43,Artikelstamm!$V$3:$V$729)
A44: Möbel | B44: =COUNTIF(Artikelstamm!$H$3:$H$729,$A44) | C44: =SUMPRODUCT((Artikelstamm!$H$3:$H$729=$A44)*Artikelstamm!$N$3:$N$729*Artikelstamm!$AE$3:$AE$729) | D44: =SUMIF(Artikelstamm!$H$3:$H$729,$A44,Artikelstamm!$V$3:$V$729)
A45: Pflanzen | B45: =COUNTIF(Artikelstamm!$H$3:$H$729,$A45) | C45: =SUMPRODUCT((Artikelstamm!$H$3:$H$729=$A45)*Artikelstamm!$N$3:$N$729*Artikelstamm!$AE$3:$AE$729) | D45: =SUMIF(Artikelstamm!$H$3:$H$729,$A45,Artikelstamm!$V$3:$V$729)
...

Sheet Kasse
A1: Kassenbuch Barverkäufe
A2: Pflicht bei einer GmbH (GoBD): jede Bareinnahme am selben Tag erfassen. Am Verkaufstag reicht eine Sammelzeile mit der Tageseinnahme, dazu ein Zählprotokoll aufbewahren. Bitte einmal mit dem Steuerberater abstimmen, in welcher Form er die Daten haben will.
A4: Datum | B4: Beleg-Nr | C4: Vorgang / Käufer | D4: Einnahme | E4: USt (steuerfrei) | F4: Betrag | G4: Ausgabe | H4: Kassenbestand
C5: Anfangsbestand Kasse | H5: 0
A6: 46308 | B6: 4000117 | C6: Jonathan Kleinknecht | D6: 100 | E6: =IF(D6="","",D6-D6/1.0) | F6: =IF(D6="","",D6/1.0) | H6: =H5+IF(D6="",0,D6)-IF(G6="",0,G6)
A7: 46308 | B7: 4000118 | C7: Aljona Dura | D7: 465 | E7: =IF(D7="","",D7-D7/1.0) | F7: =IF(D7="","",D7/1.0) | H7: =H6+IF(D7="",0,D7)-IF(G7="",0,G7)
A8: 46310 | B8: 4000129 | C8: Tanja Fischer | D8: 70 | E8: =IF(D8="","",D8-D8/1.0) | F8: =IF(D8="","",D8/1.0) | H8: =H7+IF(D8="",0,D8)-IF(G8="",0,G8)
A9: 46312 | B9: 4000136 | C9: Daniela Hauser | D9: 100 | E9: =IF(D9="","",D9-D9/1.0) | F9: =IF(D9="","",D9/1.0) | H9: =H8+IF(D9="",0,D9)-IF(G9="",0,G9)
A10: 46314 | B10: 4000137 | C10: Aljona Dura | D10: 150 | E10: =IF(D10="","",D10-D10/1.0) | F10: =IF(D10="","",D10/1.0) | H10: =H9+IF(D10="",0,D10)-IF(G10="",0,G10)
A11: 46314 | B11: 4000126 | C11: Jessica Lücke | D11: 90 | E11: =IF(D11="","",D11-D11/1.0) | F11: =IF(D11="","",D11/1.0) | H11: =H10+IF(D11="",0,D11)-IF(G11="",0,G11)
A12: 46314 | B12: 4000147 | C12: Lars Hindelang | D12: 50 | E12: =IF(D12="","",D12-D12/1.0) | F12: =IF(D12="","",D12/1.0) | H12: =H11+IF(D12="",0,D12)-IF(G12="",0,G12)
E13: =IF(D13="","",D13-D13/1.0) | F13: =IF(D13="","",D13/1.0) | H13: =H12+IF(D13="",0,D13)-IF(G13="",0,G13)
E14: =IF(D14="","",D14-D14/1.0) | F14: =IF(D14="","",D14/1.0) | H14: =H13+IF(D14="",0,D14)-IF(G14="",0,G14)
E15: =IF(D15="","",D15-D15/1.0) | F15: =IF(D15="","",D15/1.0) | H15: =H14+IF(D15="",0,D15)-IF(G15="",0,G15)
E16: =IF(D16="","",D16-D16/1.0) | F16: =IF(D16="","",D16/1.0) | H16: =H15+IF(D16="",0,D16)-IF(G16="",0,G16)
E17: =IF(D17="","",D17-D17/1.0) | F17: =IF(D17="","",D17/1.0) | H17: =H16+IF(D17="",0,D17)-IF(G17="",0,G17)
E18: =IF(D18="","",D18-D18/1.0) | F18: =IF(D18="","",D18/1.0) | H18: =H17+IF(D18="",0,D18)-IF(G18="",0,G18)
E19: =IF(D19="","",D19-D19/1.0) | F19: =IF(D19="","",D19/1.0) | H19: =H18+IF(D19="",0,D19)-IF(G19="",0,G19)
E20: =IF(D20="","",D20-D20/1.0) | F20: =IF(D20="","",D20/1.0) | H20: =H19+IF(D20="",0,D20)-IF(G20="",0,G20)
E21: =IF(D21="","",D21-D21/1.0) | F21: =IF(D21="","",D21/1.0) | H21: =H20+IF(D21="",0,D21)-IF(G21="",0,G21)
E22: =IF(D22="","",D22-D22/1.0) | F22: =IF(D22="","",D22/1.0) | H22: =H21+IF(D22="",0,D22)-IF(G22="",0,G22)
E23: =IF(D23="","",D23-D23/1.0) | F23: =IF(D23="","",D23/1.0) | H23: =H22+IF(D23="",0,D23)-IF(G23="",0,G23)
E24: =IF(D24="","",D24-D24/1.0) | F24: =IF(D24="","",D24/1.0) | H24: =H23+IF(D24="",0,D24)-IF(G24="",0,G24)
... E55: =IF(D55="","",D55-D55/1.0) | F55: =IF(D55="","",D55/1.0) | H55: =H54+IF(D55="",0,D55)-IF(G55="",0,G55)

Sheet Design
A1: Design und Stammdaten
A2: Hier ändern – nicht in den anderen Blättern. Farben als HEX ohne Raute (z. B. C8102E). Die Werte werden beim Rückeinlesen übernommen und gelten dann für Angebot, Katalog und Webkatalog.
A4: Schlüssel | B4: Wert | C4: Hinweis
A5: Firma | B5: Kikripp GmbH | C5: Vollständige Firmierung, erscheint in Kopf und Fuß aller Dokumente
A6: Strasse | B6: Hermann-Schwer-Str. 1
A7: PLZ_Ort | B7: 78048 Villingen-Schwenningen
A8: Ansprechpartner | B8: Jenny Preisigke
A9: Telefon | B9: 07725 5179702 | C9: Schreibweise bitte prüfen
A10: Email | B10: saldi4kids@outlook.com
A11: Empfaenger_Firma | B11: Mediclin Königsfeld | C11: Empfänger des Angebots
A12: Empfaenger_Person | B12: Frau Jessica Rose
A13: Angebot_Nr | B13: ANG-2026-0001
A14: Angebot_Datum | B14: 15.09.2026
A15: Angebot_Gueltig_bis | B15: 15.10.2026
A16: USt_Satz_Prozent | B16: 0 | C16: Steuerfreie Lieferung gemäß § 4 Nr. 28 UStG (Entscheidung 05.10.2026) - Preise sind Endpreise
A17: Paketrabatt_Prozent | B17: 15 | C17: Nachlass beim Paketangebot
A18: Katalog_URL | B18: https://www.kikripp.de/katalog | C18: Adresse des Webkatalogs, erscheint im Klinik-Angebot
A19: Katalog_Passwort | C19: Bewusst leer - Passwort gehoert nicht ins Projekt. Vor dem Erzeugen setzen: export KIKRIPP_KATALOG_PW=...
A20: Farbe_Rot | B20: C8102E | C20: Bollenhut-Rot - nur als Akzent verwenden
A21: Farbe_Schwarz | B21: 1A1A1A | C21: Kopfzeilen und Struktur
A22: Farbe_Papier | B22: F7F5F2 | C22: warme Fläche
A23: Farbe_Grau | B23: 6B7280 | C23: Sekundärtext
A24: Farbe_Linie | B24: DCDCDC | C24: feine Linien und Rahmen
A25: Feld_Klinik | B25: E4E4E4 | C25: Ausfüllfelder für die Klinik (mittleres Grau)
A26: Feld_Intern | B26: F2F2F2 | C26: interne Ausfüllfelder (helles Grau)
A27: Zeile_Wechsel | B27: FAFAFA | C27: Zeilenwechsel in Tabellen
A28: Schrift_Excel | B28: Arial
A29: Schrift_Web | B29: Poppins | C29: Google-Font für den Webkatalog, mit Systemschrift als Rückfall
